<?xml version="1.0" encoding="UTF-8"?>
<!-- Generated by org.testng.reporters.JUnitXMLReporter -->
<testsuite hostname="MukunLaptop" ignored="1" name="Default test(failed)" tests="8" failures="2" timestamp="2020-04-04T02:57:00 SGT" time="0.051" errors="0">
  <testcase name="test2" time="0.005" classname="demo.TestNGRetryFailedDemo">
    <skipped/>
  </testcase> <!-- test2 -->
  <testcase name="test2" time="0.001" classname="demo.TestNGRetryFailedDemo">
    <skipped/>
  </testcase> <!-- test2 -->
  <testcase name="test2" time="0.001" classname="demo.TestNGRetryFailedDemo">
    <skipped/>
  </testcase> <!-- test2 -->
  <testcase name="test2" time="0.001" classname="demo.TestNGRetryFailedDemo">
    <failure type="java.lang.ArithmeticException" message="/ by zero">
      <![CDATA[java.lang.ArithmeticException: / by zero
at demo.TestNGRetryFailedDemo.test2(TestNGRetryFailedDemo.java:18)
at java.util.ArrayList.forEach(Unknown Source)
... Removed 27 stack frames]]>
    </failure>
  </testcase> <!-- test2 -->
  <testcase name="test3" time="0.002" classname="demo.TestNGRetryFailedDemo">
    <skipped/>
  </testcase> <!-- test3 -->
  <testcase name="test3" time="0.0" classname="demo.TestNGRetryFailedDemo">
    <skipped/>
  </testcase> <!-- test3 -->
  <testcase name="test3" time="0.001" classname="demo.TestNGRetryFailedDemo">
    <skipped/>
  </testcase> <!-- test3 -->
  <testcase name="test3" time="0.001" classname="demo.TestNGRetryFailedDemo">
    <failure type="java.lang.AssertionError" message="expected [true] but found [false]">
      <![CDATA[java.lang.AssertionError: expected [true] but found [false]
at demo.TestNGRetryFailedDemo.test3(TestNGRetryFailedDemo.java:24)
at java.util.ArrayList.forEach(Unknown Source)
... Removed 31 stack frames]]>
    </failure>
  </testcase> <!-- test3 -->
  <testcase name="test1" time="0.0" classname="demo.TestNGRetryFailedDemo">
    <ignored/>
  </testcase> <!-- test1 -->
</testsuite> <!-- Default test(failed) -->
